Workbook

Sheet All Disasters
A1: Disaster Row # | B1: Name | C1: Disaster Type | D1: Begin Date | E1: End Date | F1: CPI-Adjusted Cost ($M) | G1: Unadjusted Cost ($M) | H1: Deaths | I1: States | J1: Engines | K1: # Articles Found | L1: Avg Attribution Index
A2: 1 | B2: Southeast Winter Storm (January 2000) | C2: Winter Storm | D2: 20000121 | E2: 20000124 | F2: 1320.3 | G2: 706 | H2: 4 | I2: AL,FL,GA,KY,MS,NC,SC,TN,VA,WV | J2: 3,4,5,6,7,8,National | K2: =COUNTIF(Master!A$2:A$1695,A2) -> 1 | L2: =IFERROR(AVERAGEIFS(Master!P$2:P$1695,Master!A$2:A$1695,A2,Master!O$2:O$1695,"Relevant"),"")
A3: 2 | B3: Southern Severe Weather (March 2000) | C3: Severe Storm | D3: 20000328 | E3: 20000329 | F3: 1269.6 | G3: 690 | H3: 0 | I3: AL,AR,FL,GA,KY,LA,MS,NC,OK,SC,TN,TX,VA | J3: 13,14,15,3,4,5,6,7,8,National | K3: =COUNTIF(Master!A$2:A$1695,A3) -> 0 | L3: =IFERROR(AVERAGEIFS(Master!P$2:P$1695,Master!A$2:A$1695,A3,Master!O$2:O$1695,"Relevant"),"")
A4: 3 | B4: Western Fire Season (Spring-Summer 2000) | C4: Wildfire | D4: 20000301 | E4: 20000831 | F4: 1978 | G4: 1075 | H4: 0 | I4: AK,AZ,CA,CO,HI,ID,MT,NM,NV,OR,UT,WA,WY | J4: 15,16,17,18,National | K4: =COUNTIF(Master!A$2:A$1695,A4) -> 5 | L4: =IFERROR(AVERAGEIFS(Master!P$2:P$1695,Master!A$2:A$1695,A4,Master!O$2:O$1695,"Relevant"),"")
A5: 4 | B5: South Florida Flooding (October 2000) | C5: Flooding | D5: 20001003 | E5: 20001004 | F5: 1629 | G5: 900 | H5: 3 | I5: FL | J5: 3,4,5,6,National | K5: =COUNTIF(Master!A$2:A$1695,A5) -> 0 | L5: =IFERROR(AVERAGEIFS(Master!P$2:P$1695,Master!A$2:A$1695,A5,Master!O$2:O$1695,"Relevant"),"")
A6: 5 | B6: Western/Central/Southeast Drought/Heat Wave (Spring-Fall 2000) | C6: Drought | D6: 20000301 | E6: 20001130 | F6: 9344.8 | G6: 4997.2 | H6: 140 | I6: AK,AL,AZ,CA,CO,FL,GA,HI,IA,ID,IL,IN,KS,KY,MI,MN,MO,MS,MT,NC,ND,NE,NM,NV,OH,OK,OR,SC,SD,TN,TX,UT,VA,WA,WI,WV,WY | J6: 10,11,12,13,14,15,16,17,18,3,4,5,6,7,8,9,National | K6: =COUNTIF(Master!A$2:A$1695,A6) -> 1 | L6: =IFERROR(AVERAGEIFS(Master!P$2:P$1695,Master!A$2:A$1695,A6,Master!O$2:O$1695,"Relevant"),"")
A7: 6 | B7: Midwest/Ohio Valley Hail and Tornadoes (April 2001) | C7: Severe Storm | D7: 20010406 | E7: 20010411 | F7: 5508.7 | G7: 3094.8 | H7: 3 | I7: IA,IL,IN,KS,KY,MI,MN,MO,ND,NE,OH,SD,TN,WI,WV | J7: 10,11,12,13,3,4,5,6,7,8,9,National | K7: =COUNTIF(Master!A$2:A$1695,A7) -> 0 | L7: =IFERROR(AVERAGEIFS(Master!P$2:P$1695,Master!A$2:A$1695,A7,Master!O$2:O$1695,"Relevant"),"")
A8: 7 | B8: North Central Severe Weather (May 2001) | C8: Severe Storm | D8: 20010430 | E8: 20010501 | F8: 1194.3 | G8: 671 | H8: 0 | I8: IA,IL,IN,KS,MI,MN,MO,ND,NE,OH,SD,WI | J8: 10,11,12,13,8,9,National | K8: =COUNTIF(Master!A$2:A$1695,A8) -> 0 | L8: =IFERROR(AVERAGEIFS(Master!P$2:P$1695,Master!A$2:A$1695,A8,Master!O$2:O$1695,"Relevant"),"")
A9: 8 | B9: Tropical Storm Allison (June 2001) | C9: Tropical Cyclone | D9: 20010605 | E9: 20010617 | F9: 15084 | G9: 8522 | H9: 43 | I9: LA,TX | J9: 13,14,15,National | K9: =COUNTIF(Master!A$2:A$1695,A9) -> 3 | L9: =IFERROR(AVERAGEIFS(Master!P$2:P$1695,Master!A$2:A$1695,A9,Master!O$2:O$1695,"Relevant"),"")
A10: 9 | B10: Severe Storms and Tornadoes (April 2002) | C10: Severe Storm | D10: 20020427 | E10: 20020428 | F10: 3663.9 | G10: 2093.8 | H10: 7 | I10: NATIONAL | J10: National | K10: =COUNTIF(Master!A$2:A$1695,A10) -> 3 | L10: =IFERROR(AVERAGEIFS(Master!P$2:P$1695,Master!A$2:A$1695,A10,Master!O$2:O$1695,"Relevant"),"")
A11: 10 | B11: Hurricane Lili (October 2002) | C11: Tropical Cyclone | D11: 20020801 | E11: 20020805 | F11: 1932.9 | G11: 1104.5 | H11: 2 | I11: LA | J11: 13,14,15,National | K11: =COUNTIF(Master!A$2:A$1695,A11) -> 0 | L11: =IFERROR(AVERAGEIFS(Master!P$2:P$1695,Master!A$2:A$1695,A11,Master!O$2:O$1695,"Relevant"),"")
A12: 11 | B12: Tropical Storm Isidore (September 2002) | C12: Tropical Cyclone | D12: 20020925 | E12: 20020927 | F12: 2001 | G12: 1150 | H12: 5 | I12: AL,LA,MS | J12: 13,14,15,6,7,8,National | K12: =COUNTIF(Master!A$2:A$1695,A12) -> 4 | L12: =IFERROR(AVERAGEIFS(Master!P$2:P$1695,Master!A$2:A$1695,A12,Master!O$2:O$1695,"Relevant"),"")
A13: 12 | B13: Eastern Tornadoes and Severe Storms (November 2002) | C13: Severe Storm | D13: 20021109 | E13: 20021111 | F13: 1252.8 | G13: 720 | H13: 28 | I13: CT,DE,FL,GA,MA,MD,ME,NC,NH,NJ,NY,PA,RI,SC,VA,VT,WV | J13: 1,2,3,4,5,6,National | K13: =COUNTIF(Master!A$2:A$1695,A13) -> 1 | L13: =IFERROR(AVERAGEIFS(Master!P$2:P$1695,Master!A$2:A$1695,A13,Master!O$2:O$1695,"Relevant"),"")
... A314: 313 | B314: Southern/Eastern/Northwestern Drought and Heat Wave (2024) | C314: Drought | D314: 20240101 | E314: 20241231 | F314: 5417 | G314: 5311 | H314: 136 | I314: AL,AR,CT,DE,FL,GA,ID,KY,LA,MA,MD,ME,MS,MT,NC,NH,NJ,NY,OK,OR,PA,RI,SC,TN,TX,VA,VT,WA,WV | J314: 1,13,14,15,16,17,18,2,3,4,5,6,7,8,National | K314: =COUNTIF(Master!A$2:A$1695,A314) -> 22 | L314: =IFERROR(AVERAGEIFS(Master!P$2:P$1695,Master!A$2:A$1695,A314,Master!O$2:O$1695,"Relevant"),"")

Sheet Master
A1: Disaster Row # | B1: Article # | C1: Name | D1: Disaster Type | E1: Begin Date | F1: End Date | G1: CPI-Adjusted Cost ($M) | H1: Unadjusted Cost ($M) | I1: Deaths | J1: States | K1: Engines | L1: URL | M1: Title | N1: Snippet | O1: Relevance | P1: Attribution Index | Q1: National Newspaper | R1: Calibration Sample | S1: Full Article Text
A2: 1 | B2: 1 | C2: Southeast Winter Storm (January 2000) | D2: Winter Storm | E2: 20000121 | F2: 20000124 | G2: 1320.3 | H2: 706 | I2: 4 | J2: AL,FL,GA,KY,MS,NC,SC,TN,VA,WV | K2: 3,4,5,6,7,8,National | L2: https://www.nytimes.com/2000/01/24/us/500000-homes-left-dark-by-ice-storm-in-southeast.html | M2: 500000 Homes Left Dark By Ice Storm in Southeast | N2: Jan 24, 2000 ... Winter storm sweeps Southeast, from northeast Georgia to central ... 24, 2000, Section A, Page 12 of the National edition with the ... | Q2: =IF(SUMPRODUCT(--ISNUMBER(SEARCH('National Domains'!$A$2:$A$48,L2)))>0,"Yes","No") -> Yes | R2: =IF(COUNTIFS(Calibration!$A:$A,A2,Calibration!$B:$B,B2)>0,"Yes","No") -> Yes
A3: 3 | B3: 1 | C3: Western Fire Season (Spring-Summer 2000) | D3: Wildfire | E3: 20000301 | F3: 20000831 | G3: 1978 | H3: 1075 | I3: 0 | J3: AK,AZ,CA,CO,HI,ID,MT,NM,NV,OR,UT,WA,WY | K3: 15,16,17,18,National | L3: http://www.cnn.com/2000/US/08/13/wildfires.02/index.html | M3: Western wildfires finally lose ground - August 13, 2000 - CNN | N3: Aug 13, 2000 ... CNN.com · U.S. News ; Western wildfires finally lose ground. GALLERY. A cheatgrass fire in Nevada moves as fast as the wind will carry it -- ... | Q3: =IF(SUMPRODUCT(--ISNUMBER(SEARCH('National Domains'!$A$2:$A$48,L3)))>0,"Yes","No") -> Yes | R3: =IF(COUNTIFS(Calibration!$A:$A,A3,Calibration!$B:$B,B3)>0,"Yes","No") -> No
A4: 3 | B4: 2 | C4: Western Fire Season (Spring-Summer 2000) | D4: Wildfire | E4: 20000301 | F4: 20000831 | G4: 1978 | H4: 1075 | I4: 0 | J4: AK,AZ,CA,CO,HI,ID,MT,NM,NV,OR,UT,WA,WY | K4: 15,16,17,18,National | L4: http://www.cnn.com/2000/US/07/04/colorado.wildfires/index.html | M4: Two wildfires burn in Colorado - July 4, 2000 - CNN | N4: Jul 4, 2000 ... June 15, 2000. Wildfires rage in western United States June 14, 2000. Firefighters gain hold on Southern California wildfire. June 12, 2000 | Q4: =IF(SUMPRODUCT(--ISNUMBER(SEARCH('National Domains'!$A$2:$A$48,L4)))>0,"Yes","No") -> Yes | R4: =IF(COUNTIFS(Calibration!$A:$A,A4,Calibration!$B:$B,B4)>0,"Yes","No") -> No
A5: 3 | B5: 3 | C5: Western Fire Season (Spring-Summer 2000) | D5: Wildfire | E5: 20000301 | F5: 20000831 | G5: 1978 | H5: 1075 | I5: 0 | J5: AK,AZ,CA,CO,HI,ID,MT,NM,NV,OR,UT,WA,WY | K5: 15,16,17,18,National | L5: http://www.cnn.com/2000/US/09/12/wildfires.01/index.html | M5: West still on wildfire watch - September 12, 2000 - CNN | N5: Sep 12, 2000 ... The National Interagency Fire Center reported that several states, mostly in the West, have very high to extreme fire conditions -- Arizona, ... | Q5: =IF(SUMPRODUCT(--ISNUMBER(SEARCH('National Domains'!$A$2:$A$48,L5)))>0,"Yes","No") -> Yes | R5: =IF(COUNTIFS(Calibration!$A:$A,A5,Calibration!$B:$B,B5)>0,"Yes","No") -> No
A6: 3 | B6: 4 | C6: Western Fire Season (Spring-Summer 2000) | D6: Wildfire | E6: 20000301 | F6: 20000831 | G6: 1978 | H6: 1075 | I6: 0 | J6: AK,AZ,CA,CO,HI,ID,MT,NM,NV,OR,UT,WA,WY | K6: 15,16,17,18,National | L6: http://www.cnn.com/2000/NATURE/08/18/urban.interface/index.html | M6: Western wildfires often battled in the front yard - August 18, 2000 | N6: Aug 18, 2000 ... As the wildfires continue to burn in Montana's Bitteroot Valley, nearly a quarter of a million acres of the Bitteroot National Forest have ... | Q6: =IF(SUMPRODUCT(--ISNUMBER(SEARCH('National Domains'!$A$2:$A$48,L6)))>0,"Yes","No") -> Yes | R6: =IF(COUNTIFS(Calibration!$A:$A,A6,Calibration!$B:$B,B6)>0,"Yes","No") -> No
A7: 3 | B7: 5 | C7: Western Fire Season (Spring-Summer 2000) | D7: Wildfire | E7: 20000301 | F7: 20000831 | G7: 1978 | H7: 1075 | I7: 0 | J7: AK,AZ,CA,CO,HI,ID,MT,NM,NV,OR,UT,WA,WY | K7: 15,16,17,18,National | L7: http://www.cnn.com/2000/US/09/08/wildfires.02/index.html | M7: 'Good progress' against U.S. wildfires - September 8, 2000 - CNN | N7: Sep 8, 2000 ... By Jim Morris CNN.com Senior Writer. GALLERY. Click here for images of the ongoing fight against the wildfires. WEATHER FORECASTS. Idaho | Q7: =IF(SUMPRODUCT(--ISNUMBER(SEARCH('National Domains'!$A$2:$A$48,L7)))>0,"Yes","No") -> Yes | R7: =IF(COUNTIFS(Calibration!$A:$A,A7,Calibration!$B:$B,B7)>0,"Yes","No") -> No
A8: 5 | B8: 1 | C8: Western/Central/Southeast Drought/Heat Wave (Spring-Fall 2000) | D8: Drought | E8: 20000301 | F8: 20001130 | G8: 9344.8 | H8: 4997.2 | I8: 140 | J8: AK,AL,AZ,CA,CO,FL,GA,HI,IA,ID,IL,IN,KS,KY,MI,MN,MO,MS,MT,NC,ND,NE,NM,NV,OH,OK,OR,SC,SD,TN,TX,UT,VA,WA,WI,WV,WY | K8: 10,11,12,13,14,15,16,17,18,3,4,5,6,7,8,9,National | L8: https://www.baltimoresun.com/2000/03/14/drought-forecast-in-much-of-us-some-states-face-crisis-md-warned-to-expect-less-rain-than-usual/ | M8: Drought forecast in much of U.S.; Some states face crisis; Md ... | N8: Mar 14, 2000 ... These frequently produce heavy rains in the Northwest, drought in the Southeast and more tropical storms and hurricanes in the Atlantic Ocean. | Q8: =IF(SUMPRODUCT(--ISNUMBER(SEARCH('National Domains'!$A$2:$A$48,L8)))>0,"Yes","No") -> Yes | R8: =IF(COUNTIFS(Calibration!$A:$A,A8,Calibration!$B:$B,B8)>0,"Yes","No") -> No
A9: 8 | B9: 1 | C9: Tropical Storm Allison (June 2001) | D9: Tropical Cyclone | E9: 20010605 | F9: 20010617 | G9: 15084 | H9: 8522 | I9: 43 | J9: LA,TX | K9: 13,14,15,National | L9: https://www.chron.com/news/houston-texas/article/Tropical-Storm-Allison-takesHouston-Galveston-by-2046653.php | M9: Tropical Storm Allison takesHouston, Galveston by surprise - Chron | N9: Jun 5, 2001 ... The first named storm of the hurricane season, Tropical Storm Allison ... He is a proud native of South Africa, citizen of the United States and ... | Q9: =IF(SUMPRODUCT(--ISNUMBER(SEARCH('National Domains'!$A$2:$A$48,L9)))>0,"Yes","No") -> No | R9: =IF(COUNTIFS(Calibration!$A:$A,A9,Calibration!$B:$B,B9)>0,"Yes","No") -> No
A10: 8 | B10: 2 | C10: Tropical Storm Allison (June 2001) | D10: Tropical Cyclone | E10: 20010605 | F10: 20010617 | G10: 15084 | H10: 8522 | I10: 43 | J10: LA,TX | K10: 13,14,15,National | L10: https://www.chron.com/life/article/Fresh-news-Tropical-Storm-Allison-dumps-on-city-2048790.php | M10: Fresh news: Tropical Storm Allison dumps on city - Chron | N10: Jun 14, 2001 ... Tropical Storm Allison broke Houston's heart, but not its spirit. ... None of the hurricanes hit the United States. ... June 14, 2001. Chron ... | Q10: =IF(SUMPRODUCT(--ISNUMBER(SEARCH('National Domains'!$A$2:$A$48,L10)))>0,"Yes","No") -> No | R10: =IF(COUNTIFS(Calibration!$A:$A,A10,Calibration!$B:$B,B10)>0,"Yes","No") -> No
A11: 8 | B11: 3 | C11: Tropical Storm Allison (June 2001) | D11: Tropical Cyclone | E11: 20010605 | F11: 20010617 | G11: 15084 | H11: 8522 | I11: 43 | J11: LA,TX | K11: 13,14,15,National | L11: https://www.nytimes.com/2001/06/11/us/tropical-storm-leaves-16-dead-in-2-gulf-states.html | M11: Tropical Storm Leaves 16 Dead In 2 Gulf States - The New York Times | N11: Jun 11, 2001 ... ... Tropical Storm Allison, which left 15 people dead and about 10000 ... https://www.nytimes.com/2001/06/11/us/tropical-storm-leaves-16 ... | Q11: =IF(SUMPRODUCT(--ISNUMBER(SEARCH('National Domains'!$A$2:$A$48,L11)))>0,"Yes","No") -> Yes | R11: =IF(COUNTIFS(Calibration!$A:$A,A11,Calibration!$B:$B,B11)>0,"Yes","No") -> No
A12: 9 | B12: 1 | C12: Severe Storms and Tornadoes (April 2002) | D12: Severe Storm | E12: 20020427 | F12: 20020428 | G12: 3663.9 | H12: 2093.8 | I12: 7 | J12: NATIONAL | K12: National | L12: http://www.cnn.com/2002/WEATHER/04/28/storm.deaths/index.html | M12: Twisters leave at least 6 dead - April 29, 2002 - CNN | N12: Apr 29, 2002 ... The twister system in the Midwest killed three people in three states early Sunday, while three others died in Maryland when a tornado ... | Q12: =IF(SUMPRODUCT(--ISNUMBER(SEARCH('National Domains'!$A$2:$A$48,L12)))>0,"Yes","No") -> Yes | R12: =IF(COUNTIFS(Calibration!$A:$A,A12,Calibration!$B:$B,B12)>0,"Yes","No") -> No
A13: 9 | B13: 2 | C13: Severe Storms and Tornadoes (April 2002) | D13: Severe Storm | E13: 20020427 | F13: 20020428 | G13: 3663.9 | H13: 2093.8 | I13: 7 | J13: NATIONAL | K13: National | L13: http://www.cnn.com/2002/WEATHER/04/29/storm.deaths/index.html | M13: Killer tornado becomes one for the books in Maryland - April 29, 2002 | N13: Violent storms kill at least 6 in 4 states. April 29, 2002 Posted: 11:07 PM EDT (0307 GMT) ... "One of the strongest tornadoes ever to strike the state of ... | Q13: =IF(SUMPRODUCT(--ISNUMBER(SEARCH('National Domains'!$A$2:$A$48,L13)))>0,"Yes","No") -> Yes | R13: =IF(COUNTIFS(Calibration!$A:$A,A13,Calibration!$B:$B,B13)>0,"Yes","No") -> No
... A1695: 313 | B1695: 22 | C1695: Southern/Eastern/Northwestern Drought and Heat Wave (2024) | D1695: Drought | E1695: 20240101 | F1695: 20241231 | G1695: 5417 | H1695: 5311 | I1695: 136 | J1695: AL,AR,CT,DE,FL,GA,ID,KY,LA,MA,MD,ME,MS,MT,NC,NH,NJ,NY,OK,OR,PA,RI,SC,TN,TX,VA,VT,WA,WV | K1695: 1,13,14,15,16,17,18,2,3,4,5,6,7,8,National | L1695: https://www.washingtonpost.com/weather/2024/12/19/drought-southwest-rain-las-vegas/ | M1695: Drought deepens in the Southwest, driven by little rain and extreme ... | N1695: Dec 19, 2024 ... Drought is deepening in the Southwestern United States ... An extraordinary heat wave in October brought record temperatures to Phoenix for 21 ... | Q1695: =IF(SUMPRODUCT(--ISNUMBER(SEARCH('National Domains'!$A$2:$A$48,L1695)))>0,"Yes","No") -> Yes | R1695: =IF(COUNTIFS(Calibration!$A:$A,A1695,Calibration!$B:$B,B1695)>0,"Yes","No") -> No

Sheet Active
A1: Disaster Row # | B1: Article # | C1: Name | D1: Disaster Type | E1: Begin Date | F1: End Date | G1: CPI-Adjusted Cost ($M) | H1: Unadjusted Cost ($M) | I1: Deaths | J1: States | K1: Engines | L1: URL | M1: Title | N1: Snippet | O1: Relevance | P1: Attribution Index | Q1: National Newspaper | R1: Calibration Sample | S1: Full Article Text
A2: =_xlfn._xlws.FILTER(Master!A2:S1695,Master!O2:O1695="Relevant","No rows tagged as 'Relevant' yet") -> No rows tagged as 'Relevant' yet

Sheet Trash
A1: Disaster Row # | B1: Article # | C1: Name | D1: Disaster Type | E1: Begin Date | F1: End Date | G1: CPI-Adjusted Cost ($M) | H1: Unadjusted Cost ($M) | I1: Deaths | J1: States | K1: Engines | L1: URL | M1: Title | N1: Snippet | O1: Relevance | P1: Attribution Index | Q1: National Newspaper | R1: Calibration Sample | S1: Full Article Text
A2: =_xlfn._xlws.FILTER(Master!A2:S1695,Master!O2:O1695="Trash","No rows tagged as 'Trash' yet") -> No rows tagged as 'Trash' yet

Sheet National Domains
A1: Domain
A2: aim.org
A3: anavecianasuarez.com
A4: apnews.com
A5: baltimoresun.com
A6: baytobaynews.com
A7: bloggingawaydebt.com
A8: bostonglobe.com
A9: cleverdude.com
A10: cnn.com
A11: computerworld.com
A12: dailyvoice.com
... A48: wvnews.com

Sheet Calibration
A1: Disaster Row # | B1: Article # | C1: Name | D1: Disaster Type | E1: Begin Date | F1: End Date | G1: States | H1: URL | I1: Title | J1: Snippet | K1: Full Article Text | L1: Human Relevance | M1: Human Attribution Category | N1: Human Attribution Score | O1: Human D-Subtype | P1: Human Contested | Q1: LLM Relevance | R1: LLM Attribution Category | S1: LLM Attribution Score | T1: LLM D-Subtype | U1: LLM Contested | V1: Notes
A2: 1 | B2: 1 | C2: Southeast Winter Storm (January 2000) | D2: Winter Storm | E2: 20000121 | F2: 20000124 | G2: AL,FL,GA,KY,MS,NC,SC,TN,VA,WV | H2: https://www.nytimes.com/2000/01/24/us/500000-homes-left-dark-by-ice-storm-in-southeast.html | I2: 500000 Homes Left Dark By Ice Storm in Southeast | J2: Jan 24, 2000 ... Winter storm sweeps Southeast, from northeast Georgia to central ... 24, 2000, Section A, Page 12 of the National edition with the ... | N2: =IF(M2="","",IF(M2="A",1,IF(M2="B",0.5,IF(M2="C",0,IF(M2="D",-1,IF(M2="E",0,"")))))) | S2: =IF(R2="","",IF(R2="A",1,IF(R2="B",0.5,IF(R2="C",0,IF(R2="D",-1,IF(R2="E",0,""))))))
A3: 11 | B3: 4 | C3: Tropical Storm Isidore (September 2002) | D3: Tropical Cyclone | E3: 20020925 | F3: 20020927 | G3: AL,LA,MS | H3: https://www.washingtonpost.com/archive/politics/2002/10/03/500000-ordered-to-flee-as-lili-nears-gulf-coast/858d3b42-aa47-435e-8a0e-ebc69afd9872/ | I3: 500000 Ordered to Flee As Lili Nears Gulf Coast | J3: Oct 2, 2002 ... It is potentially far more destructive than last week's Tropical Storm Isidore. Forecasters upgraded Lili to a Category 4 hurricane, the ... | K3: NEW ORLEANS, Oct. 2 -- -- Nearly 500,000 residents of coastal Louisiana and Texas were told to evacuate today as the Gulf Coast braced for Hurricane Lili, a storm intensifying in strength as it aimed for a region still recovering from a tropical storm a week ago. Lili was surging up from the Caribbean today with 140-mph winds and was expected to make landfall Thursday morning. It is potentially far more destructive than last week's Tropical Storm Isidore. Forecasters upgraded Lili to a Category 4 hurricane, the second most powerful. It has already killed seven on Jamaica and St. Vincent and forced thousands of Cubans to flee their homes. "This has the potential to kill hundreds," said Max Mayfield, director of the National Hurricane Center in Miami. "Damage is going to be extensive. You better not get too close to this one." In the coastal area straddling Texas and Louisiana, weary residents still cleaning up from last week's $100 million in damage boarded up windows, sand-bagged doors, and braced for potential devastation. A hurricane warning extended from east of High Island, Tex., to the mouth of the Mississippi River in southeastern Louisiana. "We're getting ready for the real thing," said Ruth Fontenot, the mayor of New Iberia, a Cajun town in Louisiana's rice and sugar region, and a near bull's-eye in the storm's projected path. "It's increasingly gloomy in New Iberia." Fearful of a "catastrophic" potential 20-foot storm surge that would inundate the picturesque regional capital 140 miles west of New Orleans, she had just ordered the evacuation of all 35,000 citizens, and sent her own children out of town. New Iberia is only 10 miles from Vermilion Bay, which opens into the Gulf of Mexico. "The message I've been sending out is, 'Leave,' " Fontenot said. New Orleans, at the storm's projected eastern edge, remained calm today though area schools were to be closed Thursday, City Hall was ordered shut except for "essential" personnel, and Mayor Ray Nagin urged residents to stay close to home. "This is a very, very potent storm," Nagin said. Wind gusts of 30 to 40 mph were buffeting the city tonight. New Orleans was battered by heavy rain last week and suffered some flooding but quickly recovered thanks to its battery of 22 heavy pumping stations. States of emergency were declared in Louisiana and Texas. In Texas, officials urged 250,000 people in the Beaumont-Port Arthur area and 80,000 in Orange County to go inland, including 3,000 prisoners who were moved to jails away from the coast. Coastal ports in Louisiana that handle substantial percentages of the nation's oil imports were shut down. NASA's Mission Control in Houston was shut down, postponing today's scheduled space shuttle launch at Cape Canaveral, about 900 miles away. It was the first time in 41 years of manned space flights that bad weather in Houston prevented a Florida launch. In wild and marshy Cameron Parish, on Louisiana's sparsely populated southwestern coast, nearly the entire population of 10,000 people had been evacuated by this afternoon. "We're definitely going to get something out of this one," said sheriff's deputy Ed Racca. But he said residents had remained calm through the first evacuation in 10 years. "The older folks are used to this kind of stuff," Racca said. Roads north of Cameron Parish were reported clogged with heavy traffic. In Creole, a few miles from the gulf, "Everyone's pretty much gone," Michelle Trahan said this afternoon. "It's very quiet, very deserted," she said. She was waiting for her husband, a Cameron Parish police juror (county commissioner) to finish boarding up houses, before leaving herself. In New Iberia, residents and city workers worked feverishly throughout the afternoon at sand-bagging doors. "We're going to make it," said Fontenot, the mayor. "It's just not going to be very pleasant." | L3: Trash | N3: =IF(M3="","",IF(M3="A",1,IF(M3="B",0.5,IF(M3="C",0,IF(M3="D",-1,IF(M3="E",0,"")))))) | S3: =IF(R3="","",IF(R3="A",1,IF(R3="B",0.5,IF(R3="C",0,IF(R3="D",-1,IF(R3="E",0,""))))))
A4: 12 | B4: 1 | C4: Eastern Tornadoes and Severe Storms (November 2002) | D4: Severe Storm | E4: 20021109 | F4: 20021111 | G4: CT,DE,FL,GA,MA,MD,ME,NC,NH,NJ,NY,PA,RI,SC,VA,VT,WV | H4: https://www.capecodtimes.com/story/news/2002/11/12/deadly-winds/50957526007/ | I4: Deadly winds - Cape Cod Times | J4: Nov 12, 2002 ... Residents of Mossy Grove, Tenn., sift through the wreckage left by a tornado. Savage rash of twisters slices across U.S., killing at least 35 ... | K4: Savage rash of twisters slices across U.S., killing at least 35 Tennessee, Alabama worst hit search for missing continues Violent storms, including more than 70 tornadoes, blew across the nation early yesterday, slashing through small towns, splintering buildings and trees, twirling semi-trucks and cars and killing at least 35 people in a swath that stretched from the Gulf of Mexico to the Great Lakes. Starting late Saturday, the storms' fury mounted and swept from Louisiana, through Mississippi, Alabama, Tennessee and Ohio into Pennsylvania. early yesterday morning, the winds had demolished more than half of the two dozen houses that made up Mossy Grove, Tenn., a hamlet 40 miles west of Knoxville. Officials estimated more than a third of the structures were destroyed in Carbon Hill, Ala., a town of 2,071 people northwest of Birmingham. The deaths were most numerous in Tennessee where 16 people died, including seven in Mossy Grove. Another 12 were killed in Alabama, including seven in Carbon Hill. Five died in Ohio and one each in Mississippi and Pennsylvania. More than 200 people were injured. It was the deadliest swarm of tornadoes the nation has suffered since 1999 when at least 70 twisters killed more than 45 people over two days in Kansas and Oklahoma. Some places had only a few minutes' notice before the tornadoes swirled into town. In Van Wert, Ohio, that was just enough time to save dozens of people at the local movie theater. A manager heard a weather report on the radio as showings of "The Santa Clause 2" and "My Big Fat Greek Wedding" were ending and herded customers into hallways and restrooms - three cars blew into the theater and the roof collapsed on the blue-cushioned seats. "It wiped out three factories," said Larry Blakeley, 53, who lives about two miles from where the tornado touched down in Van Wert. "We had high winds and lightning. There are police cars and National Guard and you can't get close to where it happened." Radio pleas to the missingThe hardest-hit section in Tennessee included a five-mile stretch of Morgan County, which includes Mossy Grove. Rescuers spent yesterday combing through the wreckage. As the day ended, dozens of people were still missing. Local radio stations read the names of the missing over the airways and asked them to contact authorities if they heard their names. In some areas, phone calls on the lines that were working were so jammed that calls were not going through. Authorities were confident most people had fled their homes to safet would be accounted for soon. Still, the search was complicated by the devastation. "Emergency crews are out searching for people," said Amy Smith, a police dispatcher in nearby Oliver Springs. But she added, "The phone lines are down. They're without electric. It's going to be that way for a while." Officials from the Red Cross and emergency management teams spread out to assess the damage, and to provide those left homeless with food and shelter. In Alabama, Gov. Don Siegelman said it would take residents a long time to recover. "It's like somebody wrapped up sticks of dynamite and just blew these homes into little tiny pieces," Siegelman told reporters as he toured affected areas. "Clearly we've got to get money to these communities. But it's not so much the financial help at this point but the spiritual help that they need. We're going to do everything we can to get their lives, their homes back together." Winds hit an estimated 140 mph in Tennessee with torrential rain and golf-ball-size hail. The volatile weather was caused by unseasonably high temperatures, followed by a cold front pushing down from the north, creating optimal conditions for tornadoes, said Mark Linhares, a National Weather Service meteorologist based in Birmingham. Rare widespread twistersThe breadth of the storms was reminiscent of a similar tornado outbreak in November 1992 when a string of tornadoes sprang up in Texas and moved northeast. Ninety-four tornadoes resulted and 26 people were killed, 15 of them in Mississippi. But such widespread outbreaks are not common. In Alabama, nine people died in Walker County as a line of thunderstorms packing high winds and spinning off tornadoes rolled through the northern part of the state. In Georgia, heavy damage was reported near the town of Tate, about 45 miles north of Atlanta. In Tennessee, the tornadoes came in two waves. Late Saturda early Sunday, twisters skipped across western and middle Tennessee, killing three people. On Sunday night another line of storms crossed the state - this time south and east of Nashville. Two people, including a 10-year-old boy, were killed and 15 people were injured in Coffee County when two mobile home parks, three houses and a church were damaged near Manchester, about 60 miles southeast of Nashville, on Sunday night. | L4: Relevant | M4: C | N4: =IF(M4="","",IF(M4="A",1,IF(M4="B",0.5,IF(M4="C",0,IF(M4="D",-1,IF(M4="E",0,"")))))) -> 0 | S4: =IF(R4="","",IF(R4="A",1,IF(R4="B",0.5,IF(R4="C",0,IF(R4="D",-1,IF(R4="E",0,""))))))
A5: 14 | B5: 1 | C5: U.S. Drought (Spring-Fall 2002) | D5: Drought | E5: 20020301 | F5: 20021130 | G5: NATIONAL | H5: https://www.cnn.com/2002/WEATHER/07/22/us.drought/index.html | I5: Far-reaching drought chokes much of U.S. - July 22, 2002 - CNN | J5: Jul 22, 2002 ... The last major drought in the United States occurred in the late 1980s and had an estimated economic impact of nearly $40 billion. The ... | K5: (CNN) -- Four years without adequate rainfall have left a broad quilt of browned lawns, withered crops and scorched forests across much of the United States. But for Jeff Tranel, an agriculture and business economist with the Colorado State University extension service, it's what's not there that indicates how tough things are. "I'm out in the country quite a bit, and there are very few cows left," Tranel said recently. "In one county, Huerfano County, the 1997 census of agriculture data showed 28,000 beef cows in that county. A month ago, talking to ranchers, they said if you could find 1,000 to 5,000 cows, you would be lucky." The disappearance of thousands of cows from the heart of cattle country is a symptom of the severe drought that has gripped most of the West and much of the Southeast for four years. With nearly half the continental United States suffering from extremely dry conditions, some observers say it's the worst dry spell the country has seen in a generation -- perhaps two. "This drought is widespread and pretty intense over some large areas that rival those of the '50s," said Mark Svoboda, a climatologist at the National Drought Mitigation Center in Lincoln, Nebraska. "What we haven't seen maybe is the long-term heat, year after year after year, that we saw in the '30s." The effects have been seen most dramatically in Colorado, New Mexico and Arizona, where kiln-dry timberland exploded into a string of wildfires. More than 3.2 million acres have been burned this year, roughly twice the 10-year average, federal fire officials report. The U.S. Department of Agriculture has declared the entire state of Utah and numerous counties in Colorado, California, New Mexico and Arizona agricultural disaster areas, making farmers and ranchers in those regions eligible for federal emergency loans. The department also has opened millions of acres across 18 states from its Conservation Reserve Program for grazing and hay harvesting as ranchers have been forced to sell entire herds of cattle at a loss rather than keep them on drought-stricken pastureland. The last major drought in the United States occurred in the late 1980s and had an estimated economic impact of nearly $40 billion. The economic impact of the current drought differs among regions and sectors, Svoboda said, "but I think it's safe to say when it's all said and done, this one is going to be right up there. When we start looking at all the impacts, it's going to be in the billions of dollars." After years of drought in the Southwest and the Rockies, the High Plains states are starting to feel the pinch as well. In South Dakota, rainfall is about half of normal for much of the state, said Michael Held, administrative director for the South Dakota Farm Bureau. "In the central third of the state, most of the crops -- wheat as well as corn and soybeans -- have been severely damaged to completely ruined," he said. The drought is also causing problems for some of the fastest-growing cities in the increasingly urbanized Sunbelt, from Atlanta to Albuquerque. In New Mexico and southwestern Texas, only about 2 percent of the water that normally flows into Rio Grande has reached the river this year, said Barry Wirth, a spokesman for the U.S. Bureau of Reclamation. Along the Colorado River, which feeds some of the West's biggest cities -- including Las Vegas, Phoenix and Los Angeles -- water levels in major reservoirs like Lake Powell and Lake Mead are 50 to 60 feet below normal, Wirth said." It appears that we are on track right now to be equal to or worse than 1977, which was the worst drought year on record since Lake Powell was created. So we are in pretty stricken shape right now," he said. Residents of many of these cities are struggling with restrictions on water use even as more and more people are moving in. In Georgia, all 15 counties in metropolitan Atlanta are under water restrictions that allow outdoor watering only from 10 p.m. to 10 a.m. on alternate days. Lake Lanier, the major source of water for the area's nearly 4 million people, has been down as low as 12 feet below full pool in recent years: It is currently about 7 feet below normal. "We're only releasing the minimum flows necessary to preserve water quality in the system and water supply where needed," said Pat Robbins, a spokesman for the Army Corps of Engineers. "In other words, we've got it down to the absolute minimum that we can do, but we've got to maintain water quality and supply where it's needed." In Denver, city officials patrol enforce limits that allow homeowners to water lawns only every third day. Penalties range from a warning for first offenders to a $250 fine and the ultimate sanction -- having water cut off. "Our major job is to educate our customers on what they need to do," said Robert Trujillo, a member of the city's "Sod Squad." "Mostly, people understand. I haven't had anyone get really angry with me." The prospects for the future are uncertain. What forecasters are banking on to relieve the drought is the development of the recurring Pacific weather system known as El Nino. Scientists announced earlier this month that the phenomenon -- an above-average warming of eastern Pacific waters that typically occurs every four to five years -- should ease drought conditions in the Southeast and give the northern United States a mild winter. But continued concern can be seen in the picturesque snows atop the peaks of the Rockies. Mountain snowpacks serve as natural reservoirs that provide much of the next season's water supply for the West -- are currently between 25 percent to 40 percent of what observers consider normal, Svoboda said. "What's going be the real kicker is what happens this winter," Svoboda said. "Is this El Nino going to develop? It looks like it is, but is it going to be very strong? No, it doesn't look like it's going to be very strong. I think the jury's still out as to how beneficial this El Nino is going to be." The drought patrol, also known as the "Sod Squad," seeks out violations of water restrictions in Denver. | L5: Relevant | M5: C | N5: =IF(M5="","",IF(M5="A",1,IF(M5="B",0.5,IF(M5="C",0,IF(M5="D",-1,IF(M5="E",0,"")))))) -> 0 | S5: =IF(R5="","",IF(R5="A",1,IF(R5="B",0.5,IF(R5="C",0,IF(R5="D",-1,IF(R5="E",0,""))))))
A6: 20 | B6: 6 | C6: California Wildfires (Fall 2003) | D6: Wildfire | E6: 20030901 | F6: 20031130 | G6: CA | H6: https://www.latimes.com/archives/la-xpm-2003-oct-31-me-main31-story.html | I6: Weather Cools Wildfires' Fury - Los Angeles Times | J6: Oct 31, 2003 ... Northridge earthquake -- An article in Friday's Section A about the Southern California wildfires gave the wrong date for the Northridge ... | K6: A cloud bank carried welcome Pacific moisture to Southern California’s mountains Thursday, bringing badly needed relief to firefighters battling twin foes of fire and fatigue. Six fires, by some measures the most devastating in California history, continued to burn out of control in Los Angeles, Ventura, San Bernardino and San Diego counties. But the most dangerous of them appeared to be moving away from any towns, and there was a sense on the front lines that the worst may have passed. “This weather is so bizarre,” said Rancho Santa Fe Fire Department Capt. Gary Snavely, who was deployed to save the San Diego mountain town of Julian. “This town is threatened and on the brink of burning yesterday. And now it’s raining.” Julian, a historic gold mining town, appeared to have been spared, as was most of Lake Arrowhead. Fires were beaten back from communities in Ventura and northern Los Angeles counties. Still, there were new losses Thursday, including most of the community of Harrison Park in San Diego County. And any relief came tinged with an awareness that nature is unpredictable and the fires could yet be re-stoked by a change in winds. “I’m still very concerned,” Deputy Incident Cmdr. Donald Feser of the U.S. Forest Service said as he helped oversee the battle against the Old fire. That blaze had turned away from Arrowhead but still threatened the San Bernardino Mountain resort of Big Bear. “This fire still has a tremendous amount of potential.” Six days after the fires turned catastrophic, the California Department of Forestry and Fire Protection said this had become the worst wildfire season in the state since record-keeping began in the early 20th century. As of Wednesday, 959,955 acres had burned statewide, two-thirds in the past week in Southern California. The previous record was in 1987, when 873,000 acres burned. “We are nowhere near out of the fire season yet,” noted department spokeswoman Karen Terrill, “so it’s very likely we’ll pass the million-acre mark.” This week’s fires have been blamed for 20 deaths, including one firefighter, and the loss of at least 2,612 homes. They have scorched an estimated 745,000 acres, an area larger than Rhode Island. Losses have been estimated at more than $2 billion. “This will be the most expensive natural disaster the state has ever incurred,” Gov. Gray Davis said Thursday after an aerial tour of the devastation. “It will be the most expensive, the most severe and the longest in duration.” Despite Davis’ words, it seemed unlikely that the fires could approach the $20-billion cost of the 1993 Northridge earthquake, or the devastation of the 1906 San Francisco earthquake. Twenty-five people died and about 3,000 homes were destroyed in a much smaller area in the 1991 Oakland Hills fire. On Thursday afternoon, Gov.-elect Arnold Schwarzenegger took an hourlong helicopter tour of burned sections of the San Bernardino National Forest. Afterward, sporting a yellow CDF jacket, Schwarzenegger said he was impressed with the “incredible coordination of how this was planned. They knew this was going to happen if the forest was not cleaned up. If not for that ... many more families would not have their homes.” Schwarzenegger said he and Davis will meet today to discuss the devastation, and might fly over damaged areas together. Schwarzenegger earned a roar of applause from the roughly 1,000 assembled fire personnel when he praised their efforts, particularly in evacuating thousands of people from isolated mountain areas. “I play heroes in the movies,” he said. “These firefighters are the true heroes.” For the thousands of firefighters who have been deployed against the threat, many of them around the clock, the past week has been filled with danger, frustration, awe-inspiring spectacle, heartache and, ultimately, utter exhaustion. By Thursday, the ordeal was taking its toll. Allan Lee, 40, a Rancho Cucamonga firefighter, came down from the mountains Thursday morning after working on the Old fire in San Bernardino County since Saturday and watching hundreds of homes burn. Hungry and homesick, a cell phone call to his wife and two children brought his emotions welling to the surface. “I’m really tired,” he said, turning away and fighting back tears after hanging up the phone. “I just miss home.” San Diego The town of Julian, site of one of the most dramatic stands by firefighters, was deserted Thursday except for a dozen firetrucks parked on the main street. In front of the town hall, an American flag flew at half-staff in honor of the firefighter who died Wednesday defending the town. Two others injured in that battle were released from the hospital Thursday but a third remained in critical condition. The Cedar fire reached within 2 1/2 miles of downtown Wednesday, and spot fires licked within 300 yards. By Thursday, though, the fire was obscured by a haze of fog, mist and shifting smoke. Fire Capt. Ken Hale of the California Department of Forestry sat in his truck, exhausted, monitoring radio communications. Hale said firefighters were flanking the fire on its north and south sides in an attempt to narrow it until the two flanks meet. Hale said the main body of the fire was 25 miles wide. By Thursday night, the fire was 38% contained. The Cedar fire has been the largest in California’s recorded history, stretching over 272,318 acres from the outskirts of San Diego into the rugged terrain of the Cleveland National Forest. To attack it, firefighters have created fire breaks out of roads and bulldozed lines in the brush. But the steep, scruffy terrain made the effort difficult. It could be days before firefighters manage to narrow down the head of the fire significantly, Hale said. Meanwhile, he said, winds are expected to continue out of the west, pushing the fire to the east for the next two days. Little lies in that direction but hills and desert. The desert should serve as a natural fire break and could be where the fire finally dies. It remained dangerous Thursday. While firefighters managed to save Julian, a popular weekend destination for San Diegans, several small neighborhoods were badly damaged. The worst hit was Harrison Park, about five miles south of Julian, where at least 15 of approximately 20 homes were destroyed. “It just got nuked last night,” said Hale. Little that resembled an intact community remained in Harrison Park, which is nestled in a valley between steep hills. Trees were burned to skeletons. Homes were reduced to smoldering ruins. Chimneys stood near burnt-out truck and cars. Larry Cooke, 61, a retired fire captain with the San Diego City Fire Department, showed up to survey the destruction of his vacation cabin. The bed of his big green pickup truck contained the twisted remains of an antique cooking stove and kerosene lamps. “When I rebuild, I’ll put those in there just to remind me,” Cooke said as he chomped on an unlit cigar. He said he and his wife had been planning to fix up the cabin, which had been in his family for more than 75 years. “Well,” Cooke said, “now we won’t have any arguments on how to remodel. We have to start from scratch.” San Bernardino Two fronts of the Old fire continued to burn east of Lake Arrowhead after destroying an estimated 350 homes in the lakeside community of Cedar Glen. One was on the western edge of Big Bear Valley, near the Big Bear dam. The second was to the southwest near Keller Peak. As a layer of fog and mist moved into the area, accompanied by temperatures that cooled all the way down to the 40s, the fire slowed to a crawl. “This is the Pacific Ocean lying over our heads right now,” said Pete Dennen, the San Bernardino Fire Department division chief in charge of the Big Bear area. Still, Dennen warned against complacency. Wind gusts of up to 50 mph were blowing the fire northeastward, in a mostly harmless direction. But the blaze has mocked earlier predictions, along with efforts to contain it. “This fire can do anything,” Dennen said. “We’re just lucky, I’ll be the first to tell you.” In the 24 hours leading up to Thursday afternoon, fire crews bulldozed 20 miles of fire break between Big Bear and Highway 38, according to Feser, the Forest Service official. “The question is, ‘What would it take to put this fire out?’ ” Feser said. “I would say it would take a period of several weeks with at least three inches of rain.” Still, fire officials seemed pleased at the end of the day. A voluntary evacuation order was lifted in the high desert community of Lucerne Valley, which lies below Big Bear, as authorities became less concerned that the fire would charge down the north slope of the mountains. Although a cloud of smoke and fog hung over Big Bear, the unscathed forest areas to the east enjoyed a crystal-clear, smoke-free autumn day. The oak trees and chaparral were green and gold beneath a crisp blue sky, up to the point where Highway 38 wound around a mountain and back into the smudgy gray haze of the fire. On the eastern shore of Arrowhead, the community of Cedar Glen was a burned-out ghost town, the result of the fire that blew through on Wednesday. Falling trees and limbs, emerging out of the fog, posed a hazard to emergency crews, as did downed power lines. So hot were the flames that little silver streams marked the spots where aluminum window frames had melted. All was not devastation, however. Alan Wheeler returned to his wood-paneled split-level home in lower Cedar Glen, relieved to find the structure intact -- only 1,000 feet from where the fire tore its way through Hooks Creek late Wednesday afternoon. “I just can’t believe I’m standing in my house,” said Wheeler, a construction worker who has lived in the Arrowhead area for 29 years. “Yesterday I wouldn’t have given a plugged nickel for Cedar Glen or Arrowhead.” Wheeler said the first evacuation order came Saturday night, but he and his wife, Carolyn, decided to wait for the fire, confident that they could escape on Highway 173, which runs downhill into Hesperia. Finally, on Tuesday, they drove halfway down the mountains with two neighboring families to stay at a campground above the last checkpoint. Although the Wheelers returned home Thursday afternoon, Alan Wheeler said he was not going to unpack until the last hotspots around upper Cedar Glen were extinguished, and he was also not going to leave, even though supplies were limited to a single market and the weather had turned freezing cold. He said he would turn on his gas stove for heat through the night. “I thought about lighting a fire in the fireplace, he said. “But I don’t think that’d be a very good idea right now.” Ventura/Los Angeles The front lines of the 115,920-acre Simi Valley fire remained near the Stevenson Ranch subdivision in Los Angeles County, according to Ventura County Fire Department spokesman John Wade. Numerous bulldozer and hand crews worked to keep the flames from advancing north of Interstate 5. A reduction in winds and the cooler temperatures helped the firefighting effort. Wade said no homes had been lost in Stevenson Ranch. In Ventura County, “we don’t have any critical areas that are posing an immediate threat to any homes,” said Wade, a veteran firefighter who officially retired on Monday after nearly 38 years, but has remained at the fire base camp to lend a hand. Maintenance of the Simi fire in this area has turned to the monitoring of hot spots and continuing to build nearly 100 miles of containment line around the blaze. So far, containment is estimated at 60% and officials predict the job will be finished before Wednesday. “There’s still a lot of hard, dirty, cruddy work to be done,” Wade said. “This is when it becomes less exciting.” Near Fillmore, crews continued to battle a 63,719-acre fire burning north and northwest into the Los Padres National Forest. Hand crews and air tankers kept at the fire, which began a week ago and has been difficult to attack because it is burning in steep terrain and thick vegetation that in some areas has not burned since 1917, a Forest Service official said. Although the fire continued to spread westward within the national forest, officials said there was no imminent threat to the cities of Santa Paula, Fillmore or Ojai. | L6: Relevant | M6: C | N6: =IF(M6="","",IF(M6="A",1,IF(M6="B",0.5,IF(M6="C",0,IF(M6="D",-1,IF(M6="E",0,"")))))) -> 0 | S6: =IF(R6="","",IF(R6="A",1,IF(R6="B",0.5,IF(R6="C",0,IF(R6="D",-1,IF(R6="E",0,""))))))
A7: 27 | B7: 2 | C7: Hurricane Jeanne (September 2004) | D7: Tropical Cyclone | E7: 20040915 | F7: 20040929 | G7: FL | H7: http://www.cnn.com/2004/WEATHER/09/27/hurricane.jeanne/index.html | I7: Relief pours in as Jeanne moves north - Sep 27, 2004 - CNN | J7: Sep 27, 2004 ... A look back: Four hurricanes slam Florida in the state's worst-ever storm season. ... Scenes of Hurricane Jeanne pounding the Florida coast. | K7: TALLAHASSEE, Florida (CNN) -- Emergency officials in Florida shifted their focus from search and rescue to relief efforts Monday after Hurricane Jeanne cut a destructive path through the state. Florida Secretary of Health John Agwunobi said trucks carrying water, ice and other essentials were making their way to areas hardest hit. As of 5 p.m. ET, Jeanne had been downgraded to a tropical depression and its remnants were moving north-northeast through Georgia at about 13 mph with maximum sustained winds of 35 mph -- centered about 15 miles east-northeast of Macon. At least six people died in Florida as a result of the storm, state law enforcement officials said, and about 2.6 million customers were without power, said Secretary of Environmental Protection Colleen Castille. The storm made landfall late Saturday with 120 mph winds near the southern end of Hutchinson Island, five miles southeast of Stuart on Florida's east coast, near where Hurricane Frances came ashore September 5. It collapsed beachfront homes and ripped off roofs on a barrier island near Vero Beach in Indian River County. Concrete utility polls snapped at their bases, leaving power lines in the streets. In Melbourne, traffic was at a near standstill as residents who evacuated tried to return to their homes. City Manager Jack Schlukebier estimated that several hundred homes were damaged. About 75 percent of Melbourne residents were without power; at least 2,500 people remained in shelters, local officials said. Stuart Mayor Jeff Krauskopf said the biggest problem appeared to be roof damage. "Frances took out all the vegetation. Then when Jeanne came through, it got most of the roofs. Commercial [buildings] have had their roofs ripped off and they are being saturated with water," Krauskopf said. One of the major problems, Florida officials said, was flooding. Osceola County officials said they got 20 inches of rain as the storm passed, inundating areas that already were flooded from previous storms. Jeanne was the fourth hurricane to hit Florida in the past six weeks. "The resiliency of this state is awesome. While we're strained in terms of the resources of our state right now, we're unbowed," Gov. Jeb Bush told reporters during a visit to Pensacola, the Panhandle city that was hard hit by Hurricane Ivan nearly two weeks ago. President Bush declared Florida a major disaster area, making way for additional federal aid to supplement the state's recovery efforts. Risk Management Solutions, a catastrophe-modeling firm that works for the insurance industry, estimated Sunday that Jeanne could cause between $4 billion and $8 billion in insured losses in the United States. (Full story) State of emergency Jeanne was expected to turn to the northeast within 24 hours, the hurricane center said. Rainfall of 3 to 5 inches with isolated higher amounts can be expected along its path through Tuesday. The center warned of possible tornadoes from extreme eastern Georgia northeast through the Carolinas. Flood watches and warnings were in effect for portions of Georgia, South Carolina, North Carolina and Virginia. Valdosta in southern Georgia reported more than 5 inches of rain Monday. Georgia Gov. Sonny Perdue declared a state of emergency. Schools systems from Savannah to Augusta and west to Macon canceled classes. Thousands of airline passengers were stranded at Atlanta's Hartsfield-Jackson International Airport because Florida airports were closed or traffic was backed up. A group of nurses trying to travel home to the Tampa area was told they would probably be stuck in Atlanta for at least three days. Deadly wind and rain The Florida Highway Patrol said a man and woman from Boynton Beach drowned in a 40-foot-deep man-made lake in Deerfield Beach when their SUV left the Sawgrass Expressway and plunged into the water. Lt. Pat Santangelo, a spokesman for the Florida Highway Patrol, said the accident occurred Saturday night as the area was buffeted by high winds and driving rain. A tree along the St. Johns River fell late Sunday afternoon, killing a 15-year-old boy who was in his back yard with a friend, said Mary Justino, spokeswoman for the Clay County Sheriff's Department. She said the other teen was hurt, but the injuries weren't life-threatening. Elsewhere Sunday, a couple discovered a pickup in a deep drainage ditch in Palm Bay south of Melbourne, and its occupant had drowned, said police spokesman Barney Weiss. He said the man apparently drove into the flooded ditch by mistake. In Miami, authorities said a man was electrocuted when he touched a downed power line, and in Brevard County, the sheriff's office said a 60-year-old man was found dead in his flooded home after a hurricane party. Haiti death toll climbs Jeanne now is blamed for 1,330 deaths in Haiti, and 1,056 people have been reported missing. Haitian officials said Monday that almost 300,000 people had homes damaged or destroyed in the storm, which swept across the country September 18. Dieufort Deslorges, the head of the disaster relief section of the Haitian Department of Civil Protection, said 2,601 people were injured in the storm. | L7: Relevant | M7: C | N7: =IF(M7="","",IF(M7="A",1,IF(M7="B",0.5,IF(M7="C",0,IF(M7="D",-1,IF(M7="E",0,"")))))) -> 0 | S7: =IF(R7="","",IF(R7="A",1,IF(R7="B",0.5,IF(R7="C",0,IF(R7="D",-1,IF(R7="E",0,""))))))
A8: 42 | B8: 1 | C8: California Freeze (January 2007) | D8: Freeze | E8: 20070111 | F8: 20070117 | G8: CA | H8: https://www.washingtonpost.com/archive/business/2007/01/20/california-freeze-puts-squeeze-on-citrus-crop-span-classbankheadprices-to-rise-as-cold-curtails-orange-vegetable-harvests-span/edcfcc6e-357a-4233-904d-18badcaccac7/ | I8: California Freeze Puts Squeeze on Citrus Crop - The Washington Post | J8: Jan 20, 2007 ... California Freeze Puts Squeeze on Citrus Crop. Prices to Rise as Cold ... 2007More than 19 years ago. Make us preferred on Google. By Annys Shin. | K8: Take a big bite of that juicy navel orange. It may be the last one you enjoy for a while. More than a week of icy temperatures in California damaged an estimated $500 million or more of fruit and vegetable crops. With another dip in the mercury predicted for early next week, the worst freeze in California in eight years is not over. And consumers nationwide are likely to see its effects for weeks and even months on their grocery bills. "Consumers can expect to see higher prices on produce," Giant Food spokesman Barry F. Scher said. The only question is how much higher. Growers, retailers, economists and government officials say they will not know that until the cold spell ends and they can finish assessing the damage. "Everything is a guess at this point," said Claire Smith, a spokeswoman for Sunkist Growers, a cooperative of 6,000 California and Arizona citrus growers. Prices for navel oranges may begin rising as early as next week and might not go down until late spring, said Joel Nelsen, president of California Citrus Mutual, which represents 2,000 citrus growers. California growers do know they will be shipping fewer oranges, avocados, strawberries, artichokes, lettuce, broccoli, cabbage, cauliflower and celery. They expect, however, that the supply of strawberries could bounce back quickly. Plants that were not damaged by the cold temperatures should be able to produce more fruit in another four to six weeks, said Peggy Dillon of the California Strawberry Commission. Artichoke farmers are hopeful that freeze-damaged plants will yield another harvest in two months, said Doug Mosebar, president of the California Farm Bureau Federation. And lettuce is grown year-round in different parts of California and Arizona, so any interruption in production is likely to be temporary. Retailers may also be able to spare consumers large spikes in the prices of some commodities by turning to other domestic and foreign sources -- Mexico for avocados, Florida for Valencia oranges and grapefruit. "Giant, like every other retailer, will be looking for alternatives if we are unable to purchase from our regular vendors," Scher said. The disruption in the supply of California oranges, however, will be harder to contain, economists and industry leaders predicted. California is the nation's top producer of table citrus and about three-quarters of the annual crop was still on trees when the freeze set in during the wee hours of Jan. 12, turning the insides of much of the crop to mush. Because citrus trees produce fruit only once a year, the frigid conditions cut the harvest short. The peak market for Florida Valencia oranges begins in April. Navel oranges from Australia and South Africa don't start arriving until summer. As a result, California citrus growers are hoping for double the return on the fruit they manage to salvage, charging more and shipping some fruit with a less than perfect complexion. How much of that cost will be passed on to consumers isn't yet clear. Harris Teeter spokeswoman Jennifer Panetta said the supermarket chain's suppliers have already doubled prices for citrus fruits. But before passing those costs onto consumers, "we're going to see if we can get citrus from other parts of the world," she said. Sodexho, the food and facilities management giant based in Gaithersburg, may end up absorbing some of the increased costs for fruits and vegetables. Cafeteria prices at universities, for example, probably won't go up because of the freeze, said Dexter Tompkins, Sodexho's director of supply management for produce. "We still have to have a salad bar and offer lettuce and tomatoes on sandwiches," he said, adding, "Maybe we won't offer orange segments anymore" and instead offer pineapple or other alternatives. In fact, growers of other fruits may be in for a small windfall due to the coming orange shortage. H. Dave Carlson, president of the Washington state apple commission, said since the freeze, apple growers in his state have received more orders from distributors. He expects grocery store prices on Washington apples to inch up 10 to 15 cents a pound. But any upward pressure on prices for fruits and vegetables not directly affected by the freeze is likely to be limited, Wells Fargo economist Michael Swanson said. "These are very discrete seasonal markets," he said. Just as banana prices behave differently than orange prices, consumers should not expect to pay more for orange juice, which is made primarily with oranges from Florida, not California. The freeze has prompted speculators to drive up the price of frozen-concentrated orange-juice futures. But agricultural economists say investors need to bone up on their geography. "I would be more afraid of a freeze in Brazil," another major supplier of juicing oranges, Swanson said. "It's not a logical response." Speculators "are probably not jumping on the right horse here," University of Florida economist Tom Spreen said. If you can't bear to give up those juicy oranges just yet, you might want to start shopping now. Any fruit in stores up until now was picked before the freeze. On Wednesday, prices at local stores such as Whole Foods, Giant and Safeway reflected that, with a medium-sized navel orange costing an average of 50 cents. If you're shopping later in the week, when oranges that survived the freeze start arriving, Swanson says you might try being less picky. "The quality of the fruit is not affected, but the cosmetic appeal might be," he said. | L8: Relevant | M8: C | N8: =IF(M8="","",IF(M8="A",1,IF(M8="B",0.5,IF(M8="C",0,IF(M8="D",-1,IF(M8="E",0,"")))))) -> 0 | S8: =IF(R8="","",IF(R8="A",1,IF(R8="B",0.5,IF(R8="C",0,IF(R8="D",-1,IF(R8="E",0,""))))))
A9: 53 | B9: 8 | C9: Midwest Flooding (Summer 2008) | D9: Flooding | E9: 20080401 | F9: 20080630 | G9: IA,IL,IN,KS,MI,MN,MO,ND,NE,OH,SD,WI | H9: https://www.nytimes.com/2008/06/16/us/16midwest.html | I9: In Midwest Floods, a Broad Threat to Crops - The New York Times | J9: Jun 16, 2008 ... https://www.nytimes.com/2008/06/16/us/16midwest.html. Share full ... Midwest flooding may lie ahead. Credit...Stephen Mally for The New ... | N9: =IF(M9="","",IF(M9="A",1,IF(M9="B",0.5,IF(M9="C",0,IF(M9="D",-1,IF(M9="E",0,"")))))) | S9: =IF(R9="","",IF(R9="A",1,IF(R9="B",0.5,IF(R9="C",0,IF(R9="D",-1,IF(R9="E",0,""))))))
